Workbook

Sheet Avance 2.º corte
A1: AVANCE DEL 2.º CORTE — 70 % ENTREGADO / 30 % PENDIENTE (19/10/2026)
A2: Criterio: puntos de función transaccionales por requisito (EI, EO, EQ) de las hojas de iteración. Entregado = implementado, probado (pruebas automáticas) e integrado en la rama develop.
A4: Sprint / iteración (Jira) | B4: Módulo | C4: RF | D4: Requisito | E4: Tipo | F4: Complejidad | G4: PF | H4: Estado | I4: Pruebas automáticas
A5: Sprint 1 – Iteración 1 (Mateo) | B5: Módulo 1 — Gestión de usuarios y roles | C5: RF-01.1 | D5: Registrar usuarios | E5: EI | F5: Media | G5: 4 | H5: Entregado (70 %) | I5: 6
A6: Sprint 1 – Iteración 1 (Mateo) | B6: Módulo 1 — Gestión de usuarios y roles | C6: RF-01.2 | D6: Consultar usuarios | E6: EQ | F6: Baja | G6: 3 | H6: Entregado (70 %) | I6: 2
A7: Sprint 1 – Iteración 1 (Mateo) | B7: Módulo 1 — Gestión de usuarios y roles | C7: RF-01.3 | D7: Modificar usuarios | E7: EI | F7: Media | G7: 4 | H7: Entregado (70 %) | I7: 8
A8: Sprint 1 – Iteración 1 (Mateo) | B8: Módulo 1 — Gestión de usuarios y roles | C8: RF-01.4 | D8: Iniciar sesión | E8: EQ | F8: Baja | G8: 3 | H8: Entregado (70 %) | I8: 8
A9: Sprint 1 – Iteración 1 (Mateo) | B9: Módulo 1 — Gestión de usuarios y roles | C9: RF-01.5 | D9: Asignar roles | E9: EI | F9: Baja | G9: 3 | H9: Entregado (70 %) | I9: 6
A10: Sprint 1 – Iteración 1 (Mateo) | B10: Módulo 1 — Gestión de usuarios y roles | C10: RF-01.6 | D10: Gestionar permisos de acceso | E10: EI | F10: Media | G10: 4 | H10: Entregado (70 %) | I10: 7
A11: Sprint 1 – Iteración 1 (Mateo) | B11: Módulo 2 — Gestión de proveedores | C11: RF-02.1 | D11: Registrar proveedores | E11: EI | F11: Media | G11: 4 | H11: Entregado (70 %) | I11: 5
A12: Sprint 1 – Iteración 1 (Mateo) | B12: Módulo 2 — Gestión de proveedores | C12: RF-02.2 | D12: Consultar proveedores | E12: EQ | F12: Baja | G12: 3 | H12: Entregado (70 %) | I12: 4
A13: Sprint 1 – Iteración 1 (Mateo) | B13: Módulo 2 — Gestión de proveedores | C13: RF-02.3 | D13: Modificar información de proveedores | E13: EI | F13: Media | G13: 4 | H13: Entregado (70 %) | I13: 4
A14: Sprint 1 – Iteración 1 (Mateo) | B14: Módulo 2 — Gestión de proveedores | C14: RF-02.4 | D14: Registrar productos suministrados | E14: EI | F14: Media | G14: 4 | H14: Entregado (70 %) | I14: 6
A15: Sprint 1 – Iteración 1 (Mateo) | B15: Módulo 2 — Gestión de proveedores | C15: RF-02.5 | D15: Consultar historial de compras | E15: EO | F15: Media | G15: 5 | H15: Entregado (70 %) | I15: 3
A16: Sprint 1 – Iteración 1 (Mateo) | B16: Módulo 2 — Gestión de proveedores | C16: RF-02.6 | D16: Registrar órdenes de compra | E16: EI | F16: Alta | G16: 6 | H16: Entregado (70 %) | I16: 17
... A33: Sprint 2 – Iteración 2 (Jhorman) | B33: Módulo 4 — Productos y menú | C33: RF-04.6 | D33: Gestionar disponibilidad de productos | E33: EI | F33: Baja | G33: 3 | H33: Entregado (70 %) | I33: 3
A34: Sprint 3 – Iteración 3 (Yovany) | B34: Módulo 5 — Gestión de pedidos | C34: RF-05.1 | D34: Registrar pedidos | E34: EI | F34: Alta | G34: 6 | H34: Pendiente (30 %) | I34: —
A35: Sprint 3 – Iteración 3 (Yovany) | B35: Módulo 5 — Gestión de pedidos | C35: RF-05.2 | D35: Asociar pedidos a mesas | E35: EI | F35: Media | G35: 4 | H35: Pendiente (30 %) | I35: —
A36: Sprint 3 – Iteración 3 (Yovany) | B36: Módulo 5 — Gestión de pedidos | C36: RF-05.3 | D36: Agregar productos al pedido | E36: EI | F36: Alta | G36: 6 | H36: Pendiente (30 %) | I36: —
A37: Sprint 3 – Iteración 3 (Yovany) | B37: Módulo 5 — Gestión de pedidos | C37: RF-05.4 | D37: Modificar pedidos | E37: EI | F37: Media | G37: 4 | H37: Pendiente (30 %) | I37: —
A38: Sprint 3 – Iteración 3 (Yovany) | B38: Módulo 5 — Gestión de pedidos | C38: RF-05.5 | D38: Consultar pedidos | E38: EQ | F38: Media | G38: 4 | H38: Pendiente (30 %) | I38: —
A39: Sprint 3 – Iteración 3 (Yovany) | B39: Módulo 5 — Gestión de pedidos | C39: RF-05.6 | D39: Validar disponibilidad de insumos | E39: EQ | F39: Alta | G39: 6 | H39: Pendiente (30 %) | I39: —
A40: Sprint 3 – Iteración 3 (Yovany) | B40: Módulo 5 — Gestión de pedidos | C40: RF-05.7 | D40: Confirmar pedidos | E40: EI | F40: Media | G40: 4 | H40: Pendiente (30 %) | I40: —
A41: Sprint 3 – Iteración 3 (Yovany) | B41: Módulo 5 — Gestión de pedidos | C41: RF-05.8 | D41: Enviar pedidos a cocina | E41: EO | F41: Media | G41: 5 | H41: Pendiente (30 %) | I41: —
A42: Sprint 3 – Iteración 3 (Yovany) | B42: Módulo 5 — Gestión de pedidos | C42: RF-05.9 | D42: Consultar estado del pedido | E42: EQ | F42: Baja | G42: 3 | H42: Pendiente (30 %) | I42: —
A43: Sprint 3 – Iteración 3 (Yovany) | B43: Módulo 6 — Gestión de cocina | C43: RF-06.1 | D43: Recibir órdenes de atención | E43: EI | F43: Media | G43: 4 | H43: Pendiente (30 %) | I43: —
A44: Sprint 3 – Iteración 3 (Yovany) | B44: Módulo 6 — Gestión de cocina | C44: RF-06.2 | D44: Visualizar órdenes pendientes | E44: EQ | F44: Baja | G44: 3 | H44: Pendiente (30 %) | I44: —
A45: Sprint 3 – Iteración 3 (Yovany) | B45: Módulo 6 — Gestión de cocina | C45: RF-06.3 | D45: Organizar órdenes por llegada | E45: EQ | F45: Media | G45: 4 | H45: Pendiente (30 %) | I45: —
... A57: Sprint 3 – Iteración 3 (Yovany) | B57: Módulo 7 — Gestión de reservas | C57: RF-07.8 | D57: Actualizar estado de reservas | E57: EI | F57: Media | G57: 4 | H57: Pendiente (30 %) | I57: —
A58: Sprint 4 – Iteración 4 (Ángel) | B58: Módulo 8 — Gestión de domicilios | C58: RF-08.1 | D58: Registrar pedidos a domicilio | E58: EI | F58: Alta | G58: 6 | H58: Entregado (70 %) | I58: 8
A59: Sprint 4 – Iteración 4 (Ángel) | B59: Módulo 8 — Gestión de domicilios | C59: RF-08.2 | D59: Registrar información del cliente | E59: EI | F59: Media | G59: 4 | H59: Entregado (70 %) | I59: 5
A60: Sprint 4 – Iteración 4 (Ángel) | B60: Módulo 8 — Gestión de domicilios | C60: RF-08.3 | D60: Registrar dirección de entrega | E60: EI | F60: Media | G60: 4 | H60: Entregado (70 %) | I60: 3
A61: Sprint 4 – Iteración 4 (Ángel) | B61: Módulo 8 — Gestión de domicilios | C61: RF-08.4 | D61: Consultar pedidos a domicilio | E61: EQ | F61: Media | G61: 4 | H61: Entregado (70 %) | I61: 1
A62: Sprint 4 – Iteración 4 (Ángel) | B62: Módulo 8 — Gestión de domicilios | C62: RF-08.5 | D62: Asignar pedidos para entrega | E62: EI | F62: Media | G62: 4 | H62: Entregado (70 %) | I62: 2
A63: Sprint 4 – Iteración 4 (Ángel) | B63: Módulo 8 — Gestión de domicilios | C63: RF-08.6 | D63: Actualizar estado del domicilio | E63: EI | F63: Media | G63: 4 | H63: Entregado (70 %) | I63: 3
A64: Sprint 4 – Iteración 4 (Ángel) | B64: Módulo 8 — Gestión de domicilios | C64: RF-08.7 | D64: Registrar entrega del pedido | E64: EI | F64: Baja | G64: 3 | H64: Entregado (70 %) | I64: 1
A65: Sprint 4 – Iteración 4 (Ángel) | B65: Módulo 8 — Gestión de domicilios | C65: RF-08.8 | D65: Consultar historial de domicilios | E65: EQ | F65: Media | G65: 4 | H65: Entregado (70 %) | I65: 1
A66: Sprint 4 – Iteración 4 (Ángel) | B66: Módulo 9 — Gestión de pagos | C66: RF-09.1 | D66: Registrar pagos | E66: EI | F66: Media | G66: 4 | H66: Entregado (70 %) | I66: 4
A67: Sprint 4 – Iteración 4 (Ángel) | B67: Módulo 9 — Gestión de pagos | C67: RF-09.2 | D67: Seleccionar método de pago | E67: EI | F67: Baja | G67: 3 | H67: Entregado (70 %) | I67: 7
A68: Sprint 4 – Iteración 4 (Ángel) | B68: Módulo 9 — Gestión de pagos | C68: RF-09.3 | D68: Calcular valor total del pedido | E68: EO | F68: Media | G68: 5 | H68: Entregado (70 %) | I68: 1
...

Sheet Parametros
A1: PARÁMETROS Y FÓRMULAS BASE — StockPot (ACTUALIZADO)
A3: Tipo | B3: Complejidad | C3: PF unitario | E3: Parámetro | F3: Valor | H3: Regla clave
A4: EI | B4: Baja | C4: 3 | E4: VAF | F4: 1.08 | H4: COCOMO II se aplica UNA SOLA VEZ al proyecto completo. Las 5 iteraciones se analizan con Puntos de Función y luego se consolida el PFA global para COCOMO.
A5: EI | B5: Media | C5: 4 | E5: TDI | F5: 43
A6: EI | B6: Alta | C6: 6 | E6: LOC/PF Python | F6: 20 | H6: 20 LOC por Punto de Función
A7: EO | B7: Baja | C7: 4 | E7: COCOMO a | F7: 2.4
A8: EO | B8: Media | C8: 5 | E8: COCOMO b | F8: 1.05
A9: EO | B9: Alta | C9: 7 | E9: COCOMO c | F9: 2.5
A10: EQ | B10: Baja | C10: 3 | E10: COCOMO d | F10: 0.38
A11: EQ | B11: Media | C11: 4 | E11: Semanas del proyecto | F11: 14 | H11: Duración calendario aproximada
A12: EQ | B12: Alta | C12: 6 | E12: Semanas por iteración | F12: 5 | H12: Número de iteraciones de desarrollo
E13: Iteraciones | F13: 5
E14: Meses académicos (proyecto completo) | F14: =(F23-F22+1)/30 -> 3.2
E15: Salario desarrollador | F15: 1732412
E16: Salario administrador | F16: 2645765
E17: Salario arquitecto BD | F17: 3600000
E18: Salario QA | F18: 2539000
E19: Horas por Punto de Función | F19: 6 | H19: Esfuerzo: 6 h/PF
E20: Horas por día | F20: 8 | H20: Jornada diaria
E21: Días laborales por semana | F21: 6 | H21: Lunes a sábado
E22: Inicio del proyecto | F22: 46244 | H22: Inicio confirmado
E23: Fin del proyecto | F23: 46339 | H23: Fin confirmado
E24: Inicio del desarrollo | F24: 46279 | H24: Desarrollo desde el 14/09/2026
E25: Fin del desarrollo | F25: 46339 | H25: Fin del desarrollo
E26: % esfuerzo desarrollo | F26: 0.4 | H26: Desarrollo representa 40% del esfuerzo
E27: Horas semanales por persona | F27: =F20*F21 -> 48 | H27: 8 h/día × 6 días
E28: Días laborables proyecto | F28: =NETWORKDAYS.INTL(F22,F23,"0000001",Festivos!$A$2:$A$20) -> 80 | H28: Lunes-sábado; excluye domingos y festivos
E29: Días laborables desarrollo | F29: =NETWORKDAYS.INTL(F24,F25,"0000001",Festivos!$A$2:$A$20) -> 51 | H29: Lunes-sábado; excluye domingos y festivos

Sheet Objetivos
A1: OBJETIVOS ESPECÍFICOS — TAXONOMÍA DE BLOOM
A3: N° | B3: Objetivo específico | C3: Nivel Bloom | D3: Iteraciones donde se evidencia
A4: 1 | B4: Identificar las materias primas e insumos, así como los procesos relacionados con su registro, almacenamiento, consumo y control en restaurantes pequeños y medianos. | C4: Conocimiento | D4: 1–2
A5: 2 | B5: Describir los procesos de gestión de inventario, pedidos, ventas y consumo, así como la comunicación entre las áreas de atención y cocina. | C5: Comprensión | D5: 1–3
A6: 3 | B6: Aplicar los requisitos funcionales y no funcionales identificados para establecer las funcionalidades de StockPot orientadas a la gestión de inventario, pedidos y procesos operativos. | C6: Aplicación | D6: 2–3
A7: 4 | B7: Analizar la relación entre la disponibilidad y el consumo de insumos, los pedidos, las ventas y las actividades de las áreas de atención y cocina. | C7: Análisis | D7: 3–4
A8: 5 | B8: Evaluar la información generada sobre inventario, consumo y ventas para establecer indicadores que apoyen la toma de decisiones y el control de los procesos operativos. | C8: Evaluación | D8: 5
A9: 6 | B9: Diseñar e integrar StockPot como un sistema de gestión para restaurantes pequeños y medianos que permita controlar el inventario, gestionar pedidos, facilitar la comunicación entre atención y cocina y generar información sobre consumo y ventas. | C9: Creación | D9: 5

Sheet Iteracion 1
A1: ITERACIÓN 1 — Gestión de usuarios y roles + Gestión de proveedores
H2: PLAN DE ACTIVIDADES Y PERT
A3: Período | B3: 14/09/2026 al 24/09/2026 | C3: Días laborables | D3: 10 | E3: 1 y 2 — Identificar materias primas/procesos y describir la gestión de inventario y proveedores. | H3: ID | I3: NOMBRE DE TAREA | J3: TO | K3: TN | L3: TP | M3: TE DÍAS | N3: TE HORAS | O3: DEPENDENCIA | P3: SUPUESTOS
H4: 1 | I4: Reunión de inicio de la iteración | J4: 0.5 | K4: 0.5 | L4: 0.5 | M4: =(J4+4*K4+L4)/6 -> 0.5 | N4: =M4*Parametros!$F$20 -> 4 | P4: Reunión / seguimiento
A5: Módulo | B5: ID | C5: Requerimiento | D5: Tipo | E5: Complejidad | F5: PF | H5: 2 | I5: Planificación y análisis: revisar requerimientos y alcance | J5: 0.5 | K5: 1 | L5: 1.5 | M5: =(J5+4*K5+L5)/6 -> 1 | N5: =M5*Parametros!$F$20 -> 8 | O5: 1 | P5: Flujo de la iteración
A6: Módulo 1 — Gestión de usuarios y roles | B6: RF-01.1 | C6: Registrar usuarios | D6: EI | E6: Media | F6: =SUMIFS(Parametros!$C$4:$C$12,Parametros!$A$4:$A$12,D6,Parametros!$B$4:$B$12,E6) -> 4 | H6: 3 | I6: Planificación y análisis: validar RF y RNF | J6: 0.5 | K6: 1 | L6: 1.5 | M6: =(J6+4*K6+L6)/6 -> 1 | N6: =M6*Parametros!$F$20 -> 8 | O6: 2 | P6: Flujo de la iteración
A7: Módulo 1 — Gestión de usuarios y roles | B7: RF-01.2 | C7: Consultar usuarios | D7: EQ | E7: Baja | F7: =SUMIFS(Parametros!$C$4:$C$12,Parametros!$A$4:$A$12,D7,Parametros!$B$4:$B$12,E7) -> 3 | H7: 4 | I7: Diseño: definir arquitectura y componentes | J7: 0.5 | K7: 0.5 | L7: 0.5 | M7: =(J7+4*K7+L7)/6 -> 0.5 | N7: =M7*Parametros!$F$20 -> 4 | O7: 3 | P7: Flujo de la iteración
A8: Módulo 1 — Gestión de usuarios y roles | B8: RF-01.3 | C8: Modificar usuarios | D8: EI | E8: Media | F8: =SUMIFS(Parametros!$C$4:$C$12,Parametros!$A$4:$A$12,D8,Parametros!$B$4:$B$12,E8) -> 4 | H8: 5 | I8: Diseño: diseñar interfaz de la iteración | J8: 0.5 | K8: 0.5 | L8: 0.5 | M8: =(J8+4*K8+L8)/6 -> 0.5 | N8: =M8*Parametros!$F$20 -> 4 | O8: 4 | P8: Flujo de la iteración
A9: Módulo 1 — Gestión de usuarios y roles | B9: RF-01.4 | C9: Iniciar sesión | D9: EQ | E9: Baja | F9: =SUMIFS(Parametros!$C$4:$C$12,Parametros!$A$4:$A$12,D9,Parametros!$B$4:$B$12,E9) -> 3 | H9: 6 | I9: Diseño: diseñar base de datos de la iteración | J9: 0.5 | K9: 0.5 | L9: 0.5 | M9: =(J9+4*K9+L9)/6 -> 0.5 | N9: =M9*Parametros!$F$20 -> 4 | O9: 5 | P9: Flujo de la iteración
A10: Módulo 1 — Gestión de usuarios y roles | B10: RF-01.5 | C10: Asignar roles | D10: EI | E10: Baja | F10: =SUMIFS(Parametros!$C$4:$C$12,Parametros!$A$4:$A$12,D10,Parametros!$B$4:$B$12,E10) -> 3 | H10: 7 | I10: Diseño: revisar y aprobar diseño | J10: 0.5 | K10: 0.5 | L10: 0.5 | M10: =(J10+4*K10+L10)/6 -> 0.5 | N10: =M10*Parametros!$F$20 -> 4 | O10: 6 | P10: Flujo de la iteración
A11: Módulo 1 — Gestión de usuarios y roles | B11: RF-01.6 | C11: Gestionar permisos de acceso | D11: EI | E11: Media | F11: =SUMIFS(Parametros!$C$4:$C$12,Parametros!$A$4:$A$12,D11,Parametros!$B$4:$B$12,E11) -> 4 | H11: 8 | I11: Desarrollo: codificación FrontEnd de los módulos | J11: 1 | K11: 1.5 | L11: 2 | M11: =(J11+4*K11+L11)/6 -> 1.5 | N11: =M11*Parametros!$F$20 -> 12 | O11: 7 | P11: Flujo de la iteración
C12: Total módulo 1 | F12: =SUM(F6:F11) -> 21 | H12: 9 | I12: Desarrollo: codificación BackEnd de los módulos | J12: 1 | K12: 1.5 | L12: 2 | M12: =(J12+4*K12+L12)/6 -> 1.5 | N12: =M12*Parametros!$F$20 -> 12 | O12: 8 | P12: Flujo de la iteración
A13: Módulo 2 — Gestión de proveedores | B13: RF-02.1 | C13: Registrar proveedores | D13: EI | E13: Media | F13: =SUMIFS(Parametros!$C$4:$C$12,Parametros!$A$4:$A$12,D13,Parametros!$B$4:$B$12,E13) -> 4 | H13: 10 | I13: Desarrollo: integración de módulos | J13: 0.5 | K13: 1 | L13: 1.5 | M13: =(J13+4*K13+L13)/6 -> 1 | N13: =M13*Parametros!$F$20 -> 8 | O13: 9 | P13: Flujo de la iteración
A14: Módulo 2 — Gestión de proveedores | B14: RF-02.2 | C14: Consultar proveedores | D14: EQ | E14: Baja | F14: =SUMIFS(Parametros!$C$4:$C$12,Parametros!$A$4:$A$12,D14,Parametros!$B$4:$B$12,E14) -> 3 | H14: 11 | I14: Pruebas: elaborar y ejecutar casos de prueba | J14: 0.5 | K14: 0.5 | L14: 0.5 | M14: =(J14+4*K14+L14)/6 -> 0.5 | N14: =M14*Parametros!$F$20 -> 4 | O14: 10 | P14: Flujo de la iteración
A15: Módulo 2 — Gestión de proveedores | B15: RF-02.3 | C15: Modificar información de proveedores | D15: EI | E15: Media | F15: =SUMIFS(Parametros!$C$4:$C$12,Parametros!$A$4:$A$12,D15,Parametros!$B$4:$B$12,E15) -> 4 | H15: 12 | I15: Pruebas: aceptación y correcciones | J15: 0.5 | K15: 0.5 | L15: 0.5 | M15: =(J15+4*K15+L15)/6 -> 0.5 | N15: =M15*Parametros!$F$20 -> 4 | O15: 11 | P15: Flujo de la iteración
A16: Módulo 2 — Gestión de proveedores | B16: RF-02.4 | C16: Registrar productos suministrados | D16: EI | E16: Media | F16: =SUMIFS(Parametros!$C$4:$C$12,Parametros!$A$4:$A$12,D16,Parametros!$B$4:$B$12,E16) -> 4 | H16: 13 | I16: Reunión de cierre y revisión de la iteración | J16: 0.5 | K16: 0.5 | L16: 0.5 | M16: =(J16+4*K16+L16)/6 -> 0.5 | N16: =M16*Parametros!$F$20 -> 4 | O16: 12 | P16: Reunión / seguimiento
A17: Módulo 2 — Gestión de proveedores | B17: RF-02.5 | C17: Consultar historial de compras | D17: EO | E17: Media | F17: =SUMIFS(Parametros!$C$4:$C$12,Parametros!$A$4:$A$12,D17,Parametros!$B$4:$B$12,E17) -> 5
A18: Módulo 2 — Gestión de proveedores | B18: RF-02.6 | C18: Registrar órdenes de compra | D18: EI | E18: Alta | F18: =SUMIFS(Parametros!$C$4:$C$12,Parametros!$A$4:$A$12,D18,Parametros!$B$4:$B$12,E18) -> 6
A19: Módulo 2 — Gestión de proveedores | B19: RF-02.7 | C19: Actualizar estado de las órdenes de compra | D19: EI | E19: Media | F19: =SUMIFS(Parametros!$C$4:$C$12,Parametros!$A$4:$A$12,D19,Parametros!$B$4:$B$12,E19) -> 4
A20: Módulo 2 — Gestión de proveedores | B20: RF-02.8 | C20: Relacionar compras con inventario | D20: EI | E20: Media | F20: =SUMIFS(Parametros!$C$4:$C$12,Parametros!$A$4:$A$12,D20,Parametros!$B$4:$B$12,E20) -> 4
C21: Total módulo 2 | F21: =SUM(F13:F20) -> 34
A24: RESUMEN DE PUNTOS DE FUNCIÓN | H24: ARCHIVOS LÓGICOS INTERNOS (ILF)
A25: Componente | B25: Baja | C25: Media | D25: Alta | E25: PF | H25: ID | I25: Archivo lógico interno | J25: Complejidad | K25: PF
A26: Entrada Externa (EI) | B26: =COUNTIFS($D$6:$D$21,"EI",$E$6:$E$21,"Baja") -> 1 | C26: =COUNTIFS($D$6:$D$21,"EI",$E$6:$E$21,"Media") -> 8 | D26: =COUNTIFS($D$6:$D$21,"EI",$E$6:$E$21,"Alta") -> 1 | E26: =SUMIFS($F$6:$F$21,$D$6:$D$21,"EI") -> 41 | H26: ILF01 | I26: Usuarios | J26: Baja | K26: =IF(J26="Baja",7,IF(J26="Media",10,15)) -> 7
A27: Salida Externa (EO) | B27: =COUNTIFS($D$6:$D$21,"EO",$E$6:$E$21,"Baja") -> 0 | C27: =COUNTIFS($D$6:$D$21,"EO",$E$6:$E$21,"Media") -> 1 | D27: =COUNTIFS($D$6:$D$21,"EO",$E$6:$E$21,"Alta") -> 0 | E27: =SUMIFS($F$6:$F$21,$D$6:$D$21,"EO") -> 5 | H27: ILF02 | I27: Roles y permisos | J27: Baja | K27: =IF(J27="Baja",7,IF(J27="Media",10,15)) -> 7
A28: Consulta Externa (EQ) | B28: =COUNTIFS($D$6:$D$21,"EQ",$E$6:$E$21,"Baja") -> 3 | C28: =COUNTIFS($D$6:$D$21,"EQ",$E$6:$E$21,"Media") -> 0 | D28: =COUNTIFS($D$6:$D$21,"EQ",$E$6:$E$21,"Alta") -> 0 | E28: =SUMIFS($F$6:$F$21,$D$6:$D$21,"EQ") -> 9 | H28: ILF03 | I28: Proveedores | J28: Baja | K28: =IF(J28="Baja",7,IF(J28="Media",10,15)) -> 7
A29: PF transaccionales | E29: =SUM(E26:E28) -> 55 | H29: ILF17 | I29: Órdenes de compra | J29: Alta | K29: =IF(J29="Baja",7,IF(J29="Media",10,15)) -> 15
J30: Total ILF | K30: =SUM(K26:K29) -> 36
A33: ESTIMACIÓN DE LA ITERACIÓN
A34: PF transaccionales | B34: =E29 -> 55
A35: ILF | B35: =K30 -> 36
A36: PFSA | B36: =B34+B35 -> 91
A37: VAF | B37: =Parametros!$F$4 -> 1.08
A38: PFA | B38: =B36*B37 -> 98.28
A39: LOC/PF Python | B39: =Parametros!$F$6 -> 20
A40: LOC | B40: =B38*B39 -> 1965.6
A41: KLOC | B41: =B40/1000 -> 1.9656
A43: ESFUERZO POR PUNTOS DE FUNCIÓN
A44: PFA de la iteración | B44: =B38 -> 98.28
A45: Horas por PF | B45: =Parametros!$F$19 -> 6
...

Sheet Iteracion 2
A1: ITERACIÓN 2 — Gestión de inventario + Productos y menú
H2: PLAN DE ACTIVIDADES Y PERT
A3: Período | B3: 25/09/2026 al 06/10/2026 | C3: Días laborables | D3: 10 | E3: 1, 2 y 3 — Aplicar los requisitos al control de inventario y productos. | H3: ID | I3: NOMBRE DE TAREA | J3: TO | K3: TN | L3: TP | M3: TE DÍAS | N3: TE HORAS | O3: DEPENDENCIA | P3: SUPUESTOS
H4: 1 | I4: Reunión de inicio de la iteración | J4: 0.5 | K4: 0.5 | L4: 0.5 | M4: =(J4+4*K4+L4)/6 -> 0.5 | N4: =M4*Parametros!$F$20 -> 4 | P4: Reunión / seguimiento
A5: Módulo | B5: ID | C5: Requerimiento | D5: Tipo | E5: Complejidad | F5: PF | H5: 2 | I5: Planificación y análisis: revisar requerimientos y alcance | J5: 0.5 | K5: 1 | L5: 1.5 | M5: =(J5+4*K5+L5)/6 -> 1 | N5: =M5*Parametros!$F$20 -> 8 | O5: 1 | P5: Flujo de la iteración
A6: Módulo 3 — Gestión de inventario | B6: RF-03.1 | C6: Registrar insumos y materias primas | D6: EI | E6: Media | F6: =SUMIFS(Parametros!$C$4:$C$12,Parametros!$A$4:$A$12,D6,Parametros!$B$4:$B$12,E6) -> 4 | H6: 3 | I6: Planificación y análisis: validar RF y RNF | J6: 0.5 | K6: 1 | L6: 1.5 | M6: =(J6+4*K6+L6)/6 -> 1 | N6: =M6*Parametros!$F$20 -> 8 | O6: 2 | P6: Flujo de la iteración
A7: Módulo 3 — Gestión de inventario | B7: RF-03.2 | C7: Consultar insumos | D7: EQ | E7: Baja | F7: =SUMIFS(Parametros!$C$4:$C$12,Parametros!$A$4:$A$12,D7,Parametros!$B$4:$B$12,E7) -> 3 | H7: 4 | I7: Diseño: definir arquitectura y componentes | J7: 0.5 | K7: 0.5 | L7: 0.5 | M7: =(J7+4*K7+L7)/6 -> 0.5 | N7: =M7*Parametros!$F$20 -> 4 | O7: 3 | P7: Flujo de la iteración
A8: Módulo 3 — Gestión de inventario | B8: RF-03.3 | C8: Modificar información de insumos | D8: EI | E8: Media | F8: =SUMIFS(Parametros!$C$4:$C$12,Parametros!$A$4:$A$12,D8,Parametros!$B$4:$B$12,E8) -> 4 | H8: 5 | I8: Diseño: diseñar interfaz de la iteración | J8: 0.5 | K8: 0.5 | L8: 0.5 | M8: =(J8+4*K8+L8)/6 -> 0.5 | N8: =M8*Parametros!$F$20 -> 4 | O8: 4 | P8: Flujo de la iteración
A9: Módulo 3 — Gestión de inventario | B9: RF-03.4 | C9: Registrar entradas de inventario | D9: EI | E9: Media | F9: =SUMIFS(Parametros!$C$4:$C$12,Parametros!$A$4:$A$12,D9,Parametros!$B$4:$B$12,E9) -> 4 | H9: 6 | I9: Diseño: diseñar base de datos de la iteración | J9: 0.5 | K9: 0.5 | L9: 0.5 | M9: =(J9+4*K9+L9)/6 -> 0.5 | N9: =M9*Parametros!$F$20 -> 4 | O9: 5 | P9: Flujo de la iteración
A10: Módulo 3 — Gestión de inventario | B10: RF-03.5 | C10: Registrar salidas de inventario | D10: EI | E10: Media | F10: =SUMIFS(Parametros!$C$4:$C$12,Parametros!$A$4:$A$12,D10,Parametros!$B$4:$B$12,E10) -> 4 | H10: 7 | I10: Diseño: revisar y aprobar diseño | J10: 0.5 | K10: 0.5 | L10: 0.5 | M10: =(J10+4*K10+L10)/6 -> 0.5 | N10: =M10*Parametros!$F$20 -> 4 | O10: 6 | P10: Flujo de la iteración
A11: Módulo 3 — Gestión de inventario | B11: RF-03.6 | C11: Consultar existencias | D11: EQ | E11: Baja | F11: =SUMIFS(Parametros!$C$4:$C$12,Parametros!$A$4:$A$12,D11,Parametros!$B$4:$B$12,E11) -> 3 | H11: 8 | I11: Desarrollo: codificación FrontEnd de los módulos | J11: 1 | K11: 1.5 | L11: 2 | M11: =(J11+4*K11+L11)/6 -> 1.5 | N11: =M11*Parametros!$F$20 -> 12 | O11: 7 | P11: Flujo de la iteración
A12: Módulo 3 — Gestión de inventario | B12: RF-03.7 | C12: Establecer niveles mínimos de stock | D12: EI | E12: Baja | F12: =SUMIFS(Parametros!$C$4:$C$12,Parametros!$A$4:$A$12,D12,Parametros!$B$4:$B$12,E12) -> 3 | H12: 9 | I12: Desarrollo: codificación BackEnd de los módulos | J12: 1 | K12: 1.5 | L12: 2 | M12: =(J12+4*K12+L12)/6 -> 1.5 | N12: =M12*Parametros!$F$20 -> 12 | O12: 8 | P12: Flujo de la iteración
A13: Módulo 3 — Gestión de inventario | B13: RF-03.8 | C13: Generar alertas de stock | D13: EO | E13: Media | F13: =SUMIFS(Parametros!$C$4:$C$12,Parametros!$A$4:$A$12,D13,Parametros!$B$4:$B$12,E13) -> 5 | H13: 10 | I13: Desarrollo: integración de módulos | J13: 0.5 | K13: 1 | L13: 1.5 | M13: =(J13+4*K13+L13)/6 -> 1 | N13: =M13*Parametros!$F$20 -> 8 | O13: 9 | P13: Flujo de la iteración
A14: Módulo 3 — Gestión de inventario | B14: RF-03.9 | C14: Actualizar automáticamente el inventario | D14: EI | E14: Alta | F14: =SUMIFS(Parametros!$C$4:$C$12,Parametros!$A$4:$A$12,D14,Parametros!$B$4:$B$12,E14) -> 6 | H14: 11 | I14: Pruebas: elaborar y ejecutar casos de prueba | J14: 0.5 | K14: 0.5 | L14: 0.5 | M14: =(J14+4*K14+L14)/6 -> 0.5 | N14: =M14*Parametros!$F$20 -> 4 | O14: 10 | P14: Flujo de la iteración
C15: Total módulo 3 | F15: =SUM(F6:F14) -> 36 | H15: 12 | I15: Pruebas: aceptación y correcciones | J15: 0.5 | K15: 0.5 | L15: 0.5 | M15: =(J15+4*K15+L15)/6 -> 0.5 | N15: =M15*Parametros!$F$20 -> 4 | O15: 11 | P15: Flujo de la iteración
A16: Módulo 4 — Productos y menú | B16: RF-04.1 | C16: Registrar productos y platos | D16: EI | E16: Media | F16: =SUMIFS(Parametros!$C$4:$C$12,Parametros!$A$4:$A$12,D16,Parametros!$B$4:$B$12,E16) -> 4 | H16: 13 | I16: Reunión de cierre y revisión de la iteración | J16: 0.5 | K16: 0.5 | L16: 0.5 | M16: =(J16+4*K16+L16)/6 -> 0.5 | N16: =M16*Parametros!$F$20 -> 4 | O16: 12 | P16: Reunión / seguimiento
A17: Módulo 4 — Productos y menú | B17: RF-04.2 | C17: Consultar productos y platos | D17: EQ | E17: Baja | F17: =SUMIFS(Parametros!$C$4:$C$12,Parametros!$A$4:$A$12,D17,Parametros!$B$4:$B$12,E17) -> 3
A18: Módulo 4 — Productos y menú | B18: RF-04.3 | C18: Modificar productos y platos | D18: EI | E18: Media | F18: =SUMIFS(Parametros!$C$4:$C$12,Parametros!$A$4:$A$12,D18,Parametros!$B$4:$B$12,E18) -> 4
A19: Módulo 4 — Productos y menú | B19: RF-04.4 | C19: Asociar insumos a productos o platos | D19: EI | E19: Alta | F19: =SUMIFS(Parametros!$C$4:$C$12,Parametros!$A$4:$A$12,D19,Parametros!$B$4:$B$12,E19) -> 6
A20: Módulo 4 — Productos y menú | B20: RF-04.5 | C20: Establecer precios de venta | D20: EI | E20: Baja | F20: =SUMIFS(Parametros!$C$4:$C$12,Parametros!$A$4:$A$12,D20,Parametros!$B$4:$B$12,E20) -> 3
A21: Módulo 4 — Productos y menú | B21: RF-04.6 | C21: Gestionar disponibilidad de productos | D21: EI | E21: Baja | F21: =SUMIFS(Parametros!$C$4:$C$12,Parametros!$A$4:$A$12,D21,Parametros!$B$4:$B$12,E21) -> 3
C22: Total módulo 4 | F22: =SUM(F16:F21) -> 23
A25: RESUMEN DE PUNTOS DE FUNCIÓN | H25: ARCHIVOS LÓGICOS INTERNOS (ILF)
A26: Componente | B26: Baja | C26: Media | D26: Alta | E26: PF | H26: ID | I26: Archivo lógico interno | J26: Complejidad | K26: PF
A27: Entrada Externa (EI) | B27: =COUNTIFS($D$6:$D$22,"EI",$E$6:$E$22,"Baja") -> 3 | C27: =COUNTIFS($D$6:$D$22,"EI",$E$6:$E$22,"Media") -> 6 | D27: =COUNTIFS($D$6:$D$22,"EI",$E$6:$E$22,"Alta") -> 2 | E27: =SUMIFS($F$6:$F$22,$D$6:$D$22,"EI") -> 45 | H27: ILF04 | I27: Insumos | J27: Media | K27: =IF(J27="Baja",7,IF(J27="Media",10,15)) -> 10
A28: Salida Externa (EO) | B28: =COUNTIFS($D$6:$D$22,"EO",$E$6:$E$22,"Baja") -> 0 | C28: =COUNTIFS($D$6:$D$22,"EO",$E$6:$E$22,"Media") -> 1 | D28: =COUNTIFS($D$6:$D$22,"EO",$E$6:$E$22,"Alta") -> 0 | E28: =SUMIFS($F$6:$F$22,$D$6:$D$22,"EO") -> 5 | H28: ILF05 | I28: Movimientos de inventario | J28: Alta | K28: =IF(J28="Baja",7,IF(J28="Media",10,15)) -> 15
A29: Consulta Externa (EQ) | B29: =COUNTIFS($D$6:$D$22,"EQ",$E$6:$E$22,"Baja") -> 3 | C29: =COUNTIFS($D$6:$D$22,"EQ",$E$6:$E$22,"Media") -> 0 | D29: =COUNTIFS($D$6:$D$22,"EQ",$E$6:$E$22,"Alta") -> 0 | E29: =SUMIFS($F$6:$F$22,$D$6:$D$22,"EQ") -> 9 | H29: ILF06 | I29: Productos y platos | J29: Media | K29: =IF(J29="Baja",7,IF(J29="Media",10,15)) -> 10
A30: PF transaccionales | E30: =SUM(E27:E29) -> 59 | H30: ILF07 | I30: Recetas / composición | J30: Alta | K30: =IF(J30="Baja",7,IF(J30="Media",10,15)) -> 15
J31: Total ILF | K31: =SUM(K27:K30) -> 50
A34: ESTIMACIÓN DE LA ITERACIÓN
A35: PF transaccionales | B35: =E30 -> 59
A36: ILF | B36: =K31 -> 50
A37: PFSA | B37: =B35+B36 -> 109
A38: VAF | B38: =Parametros!$F$4 -> 1.08
A39: PFA | B39: =B37*B38 -> 117.72
A40: LOC/PF Python | B40: =Parametros!$F$6 -> 20
A41: LOC | B41: =B39*B40 -> 2354.4
A42: KLOC | B42: =B41/1000 -> 2.3544
A44: ESFUERZO POR PUNTOS DE FUNCIÓN
A45: PFA de la iteración | B45: =B39 -> 117.72
...

Sheet Iteracion 3
A1: ITERACIÓN 3 — Gestión de pedidos + Gestión de cocina
H2: PLAN DE ACTIVIDADES Y PERT
A3: Período | B3: 07/10/2026 al 19/10/2026 | C3: Días laborables | D3: 10 | E3: 2, 3 y 4 — Aplicar funcionalidades y analizar la relación entre pedidos, insumos y cocina. | H3: ID | I3: NOMBRE DE TAREA | J3: TO | K3: TN | L3: TP | M3: TE DÍAS | N3: TE HORAS | O3: DEPENDENCIA | P3: SUPUESTOS
H4: 1 | I4: Reunión de inicio de la iteración | J4: 0.5 | K4: 0.5 | L4: 0.5 | M4: =(J4+4*K4+L4)/6 -> 0.5 | N4: =M4*Parametros!$F$20 -> 4 | P4: Reunión / seguimiento
A5: Módulo | B5: ID | C5: Requerimiento | D5: Tipo | E5: Complejidad | F5: PF | H5: 2 | I5: Planificación y análisis: revisar requerimientos y alcance | J5: 0.5 | K5: 1 | L5: 1.5 | M5: =(J5+4*K5+L5)/6 -> 1 | N5: =M5*Parametros!$F$20 -> 8 | O5: 1 | P5: Flujo de la iteración
A6: Módulo 5 — Gestión de pedidos | B6: RF-05.1 | C6: Registrar pedidos | D6: EI | E6: Alta | F6: =SUMIFS(Parametros!$C$4:$C$12,Parametros!$A$4:$A$12,D6,Parametros!$B$4:$B$12,E6) -> 6 | H6: 3 | I6: Planificación y análisis: validar RF y RNF | J6: 0.5 | K6: 1 | L6: 1.5 | M6: =(J6+4*K6+L6)/6 -> 1 | N6: =M6*Parametros!$F$20 -> 8 | O6: 2 | P6: Flujo de la iteración
A7: Módulo 5 — Gestión de pedidos | B7: RF-05.2 | C7: Asociar pedidos a mesas | D7: EI | E7: Media | F7: =SUMIFS(Parametros!$C$4:$C$12,Parametros!$A$4:$A$12,D7,Parametros!$B$4:$B$12,E7) -> 4 | H7: 4 | I7: Diseño: definir arquitectura y componentes | J7: 0.5 | K7: 0.5 | L7: 0.5 | M7: =(J7+4*K7+L7)/6 -> 0.5 | N7: =M7*Parametros!$F$20 -> 4 | O7: 3 | P7: Flujo de la iteración
A8: Módulo 5 — Gestión de pedidos | B8: RF-05.3 | C8: Agregar productos al pedido | D8: EI | E8: Alta | F8: =SUMIFS(Parametros!$C$4:$C$12,Parametros!$A$4:$A$12,D8,Parametros!$B$4:$B$12,E8) -> 6 | H8: 5 | I8: Diseño: diseñar interfaz de la iteración | J8: 0.5 | K8: 0.5 | L8: 0.5 | M8: =(J8+4*K8+L8)/6 -> 0.5 | N8: =M8*Parametros!$F$20 -> 4 | O8: 4 | P8: Flujo de la iteración
A9: Módulo 5 — Gestión de pedidos | B9: RF-05.4 | C9: Modificar pedidos | D9: EI | E9: Media | F9: =SUMIFS(Parametros!$C$4:$C$12,Parametros!$A$4:$A$12,D9,Parametros!$B$4:$B$12,E9) -> 4 | H9: 6 | I9: Diseño: diseñar base de datos de la iteración | J9: 0.5 | K9: 0.5 | L9: 0.5 | M9: =(J9+4*K9+L9)/6 -> 0.5 | N9: =M9*Parametros!$F$20 -> 4 | O9: 5 | P9: Flujo de la iteración
A10: Módulo 5 — Gestión de pedidos | B10: RF-05.5 | C10: Consultar pedidos | D10: EQ | E10: Media | F10: =SUMIFS(Parametros!$C$4:$C$12,Parametros!$A$4:$A$12,D10,Parametros!$B$4:$B$12,E10) -> 4 | H10: 7 | I10: Diseño: revisar y aprobar diseño | J10: 0.5 | K10: 0.5 | L10: 0.5 | M10: =(J10+4*K10+L10)/6 -> 0.5 | N10: =M10*Parametros!$F$20 -> 4 | O10: 6 | P10: Flujo de la iteración
A11: Módulo 5 — Gestión de pedidos | B11: RF-05.6 | C11: Validar disponibilidad de insumos | D11: EQ | E11: Alta | F11: =SUMIFS(Parametros!$C$4:$C$12,Parametros!$A$4:$A$12,D11,Parametros!$B$4:$B$12,E11) -> 6 | H11: 8 | I11: Desarrollo: codificación FrontEnd de los módulos | J11: 1 | K11: 1.5 | L11: 2 | M11: =(J11+4*K11+L11)/6 -> 1.5 | N11: =M11*Parametros!$F$20 -> 12 | O11: 7 | P11: Flujo de la iteración
A12: Módulo 5 — Gestión de pedidos | B12: RF-05.7 | C12: Confirmar pedidos | D12: EI | E12: Media | F12: =SUMIFS(Parametros!$C$4:$C$12,Parametros!$A$4:$A$12,D12,Parametros!$B$4:$B$12,E12) -> 4 | H12: 9 | I12: Desarrollo: codificación BackEnd de los módulos | J12: 1 | K12: 1.5 | L12: 2 | M12: =(J12+4*K12+L12)/6 -> 1.5 | N12: =M12*Parametros!$F$20 -> 12 | O12: 8 | P12: Flujo de la iteración
A13: Módulo 5 — Gestión de pedidos | B13: RF-05.8 | C13: Enviar pedidos a cocina | D13: EO | E13: Media | F13: =SUMIFS(Parametros!$C$4:$C$12,Parametros!$A$4:$A$12,D13,Parametros!$B$4:$B$12,E13) -> 5 | H13: 10 | I13: Desarrollo: integración de módulos | J13: 0.5 | K13: 1 | L13: 1.5 | M13: =(J13+4*K13+L13)/6 -> 1 | N13: =M13*Parametros!$F$20 -> 8 | O13: 9 | P13: Flujo de la iteración
A14: Módulo 5 — Gestión de pedidos | B14: RF-05.9 | C14: Consultar estado del pedido | D14: EQ | E14: Baja | F14: =SUMIFS(Parametros!$C$4:$C$12,Parametros!$A$4:$A$12,D14,Parametros!$B$4:$B$12,E14) -> 3 | H14: 11 | I14: Pruebas: elaborar y ejecutar casos de prueba | J14: 0.5 | K14: 0.5 | L14: 0.5 | M14: =(J14+4*K14+L14)/6 -> 0.5 | N14: =M14*Parametros!$F$20 -> 4 | O14: 10 | P14: Flujo de la iteración
C15: Total módulo 5 | F15: =SUM(F6:F14) -> 42 | H15: 12 | I15: Pruebas: aceptación y correcciones | J15: 0.5 | K15: 0.5 | L15: 0.5 | M15: =(J15+4*K15+L15)/6 -> 0.5 | N15: =M15*Parametros!$F$20 -> 4 | O15: 11 | P15: Flujo de la iteración
A16: Módulo 6 — Gestión de cocina | B16: RF-06.1 | C16: Recibir órdenes de atención | D16: EI | E16: Media | F16: =SUMIFS(Parametros!$C$4:$C$12,Parametros!$A$4:$A$12,D16,Parametros!$B$4:$B$12,E16) -> 4 | H16: 13 | I16: Reunión de cierre y revisión de la iteración | J16: 0.5 | K16: 0.5 | L16: 0.5 | M16: =(J16+4*K16+L16)/6 -> 0.5 | N16: =M16*Parametros!$F$20 -> 4 | O16: 12 | P16: Reunión / seguimiento
A17: Módulo 6 — Gestión de cocina | B17: RF-06.2 | C17: Visualizar órdenes pendientes | D17: EQ | E17: Baja | F17: =SUMIFS(Parametros!$C$4:$C$12,Parametros!$A$4:$A$12,D17,Parametros!$B$4:$B$12,E17) -> 3
A18: Módulo 6 — Gestión de cocina | B18: RF-06.3 | C18: Organizar órdenes por llegada | D18: EQ | E18: Media | F18: =SUMIFS(Parametros!$C$4:$C$12,Parametros!$A$4:$A$12,D18,Parametros!$B$4:$B$12,E18) -> 4
A19: Módulo 6 — Gestión de cocina | B19: RF-06.4 | C19: Actualizar estado de preparación | D19: EI | E19: Media | F19: =SUMIFS(Parametros!$C$4:$C$12,Parametros!$A$4:$A$12,D19,Parametros!$B$4:$B$12,E19) -> 4
A20: Módulo 6 — Gestión de cocina | B20: RF-06.5 | C20: Marcar pedidos como preparados | D20: EI | E20: Baja | F20: =SUMIFS(Parametros!$C$4:$C$12,Parametros!$A$4:$A$12,D20,Parametros!$B$4:$B$12,E20) -> 3
A21: Módulo 6 — Gestión de cocina | B21: RF-06.6 | C21: Marcar pedidos como entregados | D21: EI | E21: Baja | F21: =SUMIFS(Parametros!$C$4:$C$12,Parametros!$A$4:$A$12,D21,Parametros!$B$4:$B$12,E21) -> 3
A22: Módulo 6 — Gestión de cocina | B22: RF-06.7 | C22: Notificar cambio de estado | D22: EO | E22: Media | F22: =SUMIFS(Parametros!$C$4:$C$12,Parametros!$A$4:$A$12,D22,Parametros!$B$4:$B$12,E22) -> 5
C23: Total módulo 6 | F23: =SUM(F16:F22) -> 26
A26: RESUMEN DE PUNTOS DE FUNCIÓN | H26: ARCHIVOS LÓGICOS INTERNOS (ILF)
A27: Componente | B27: Baja | C27: Media | D27: Alta | E27: PF | H27: ID | I27: Archivo lógico interno | J27: Complejidad | K27: PF
A28: Entrada Externa (EI) | B28: =COUNTIFS($D$6:$D$23,"EI",$E$6:$E$23,"Baja") -> 2 | C28: =COUNTIFS($D$6:$D$23,"EI",$E$6:$E$23,"Media") -> 5 | D28: =COUNTIFS($D$6:$D$23,"EI",$E$6:$E$23,"Alta") -> 2 | E28: =SUMIFS($F$6:$F$23,$D$6:$D$23,"EI") -> 38 | H28: ILF08 | I28: Mesas | J28: Baja | K28: =IF(J28="Baja",7,IF(J28="Media",10,15)) -> 7
A29: Salida Externa (EO) | B29: =COUNTIFS($D$6:$D$23,"EO",$E$6:$E$23,"Baja") -> 0 | C29: =COUNTIFS($D$6:$D$23,"EO",$E$6:$E$23,"Media") -> 2 | D29: =COUNTIFS($D$6:$D$23,"EO",$E$6:$E$23,"Alta") -> 0 | E29: =SUMIFS($F$6:$F$23,$D$6:$D$23,"EO") -> 10 | H29: ILF09 | I29: Pedidos | J29: Alta | K29: =IF(J29="Baja",7,IF(J29="Media",10,15)) -> 15
A30: Consulta Externa (EQ) | B30: =COUNTIFS($D$6:$D$23,"EQ",$E$6:$E$23,"Baja") -> 2 | C30: =COUNTIFS($D$6:$D$23,"EQ",$E$6:$E$23,"Media") -> 2 | D30: =COUNTIFS($D$6:$D$23,"EQ",$E$6:$E$23,"Alta") -> 1 | E30: =SUMIFS($F$6:$F$23,$D$6:$D$23,"EQ") -> 20 | H30: ILF10 | I30: Detalle de pedidos | J30: Media | K30: =IF(J30="Baja",7,IF(J30="Media",10,15)) -> 10
A31: PF transaccionales | E31: =SUM(E28:E30) -> 68 | J31: Total ILF | K31: =SUM(K28:K30) -> 32
A34: ESTIMACIÓN DE LA ITERACIÓN
A35: PF transaccionales | B35: =E31 -> 68
A36: ILF | B36: =K31 -> 32
A37: PFSA | B37: =B35+B36 -> 100
A38: VAF | B38: =Parametros!$F$4 -> 1.08
A39: PFA | B39: =B37*B38 -> 108
A40: LOC/PF Python | B40: =Parametros!$F$6 -> 20
A41: LOC | B41: =B39*B40 -> 2160
A42: KLOC | B42: =B41/1000 -> 2.16
A44: ESFUERZO POR PUNTOS DE FUNCIÓN
A45: PFA de la iteración | B45: =B39 -> 108
...

Sheet Iteracion 4
A1: ITERACIÓN 4 — Gestión de reservas + Gestión de domicilios
H2: PLAN DE ACTIVIDADES Y PERT
A3: Período | B3: 20/10/2026 al 30/10/2026 | C3: Días laborables | D3: 10 | E3: 2 y 4 — Integrar reservas y domicilios y analizar su relación con la operación. | H3: ID | I3: NOMBRE DE TAREA | J3: TO | K3: TN | L3: TP | M3: TE DÍAS | N3: TE HORAS | O3: DEPENDENCIA | P3: SUPUESTOS
H4: 1 | I4: Reunión de inicio de la iteración | J4: 0.5 | K4: 0.5 | L4: 0.5 | M4: =(J4+4*K4+L4)/6 -> 0.5 | N4: =M4*Parametros!$F$20 -> 4 | P4: Reunión / seguimiento
A5: Módulo | B5: ID | C5: Requerimiento | D5: Tipo | E5: Complejidad | F5: PF | H5: 2 | I5: Planificación y análisis: revisar requerimientos y alcance | J5: 0.5 | K5: 1 | L5: 1.5 | M5: =(J5+4*K5+L5)/6 -> 1 | N5: =M5*Parametros!$F$20 -> 8 | O5: 1 | P5: Flujo de la iteración
A6: Módulo 7 — Gestión de reservas | B6: RF-07.1 | C6: Registrar reservas | D6: EI | E6: Media | F6: =SUMIFS(Parametros!$C$4:$C$12,Parametros!$A$4:$A$12,D6,Parametros!$B$4:$B$12,E6) -> 4 | H6: 3 | I6: Planificación y análisis: validar RF y RNF | J6: 0.5 | K6: 1 | L6: 1.5 | M6: =(J6+4*K6+L6)/6 -> 1 | N6: =M6*Parametros!$F$20 -> 8 | O6: 2 | P6: Flujo de la iteración
A7: Módulo 7 — Gestión de reservas | B7: RF-07.2 | C7: Consultar reservas | D7: EQ | E7: Baja | F7: =SUMIFS(Parametros!$C$4:$C$12,Parametros!$A$4:$A$12,D7,Parametros!$B$4:$B$12,E7) -> 3 | H7: 4 | I7: Diseño: definir arquitectura y componentes | J7: 0.5 | K7: 0.5 | L7: 0.5 | M7: =(J7+4*K7+L7)/6 -> 0.5 | N7: =M7*Parametros!$F$20 -> 4 | O7: 3 | P7: Flujo de la iteración
A8: Módulo 7 — Gestión de reservas | B8: RF-07.3 | C8: Modificar reservas | D8: EI | E8: Media | F8: =SUMIFS(Parametros!$C$4:$C$12,Parametros!$A$4:$A$12,D8,Parametros!$B$4:$B$12,E8) -> 4 | H8: 5 | I8: Diseño: diseñar interfaz de la iteración | J8: 0.5 | K8: 0.5 | L8: 0.5 | M8: =(J8+4*K8+L8)/6 -> 0.5 | N8: =M8*Parametros!$F$20 -> 4 | O8: 4 | P8: Flujo de la iteración
A9: Módulo 7 — Gestión de reservas | B9: RF-07.4 | C9: Cancelar reservas | D9: EI | E9: Baja | F9: =SUMIFS(Parametros!$C$4:$C$12,Parametros!$A$4:$A$12,D9,Parametros!$B$4:$B$12,E9) -> 3 | H9: 6 | I9: Diseño: diseñar base de datos de la iteración | J9: 0.5 | K9: 0.5 | L9: 0.5 | M9: =(J9+4*K9+L9)/6 -> 0.5 | N9: =M9*Parametros!$F$20 -> 4 | O9: 5 | P9: Flujo de la iteración
A10: Módulo 7 — Gestión de reservas | B10: RF-07.5 | C10: Registrar fecha y hora de la reserva | D10: EI | E10: Baja | F10: =SUMIFS(Parametros!$C$4:$C$12,Parametros!$A$4:$A$12,D10,Parametros!$B$4:$B$12,E10) -> 3 | H10: 7 | I10: Diseño: revisar y aprobar diseño | J10: 0.5 | K10: 0.5 | L10: 0.5 | M10: =(J10+4*K10+L10)/6 -> 0.5 | N10: =M10*Parametros!$F$20 -> 4 | O10: 6 | P10: Flujo de la iteración
A11: Módulo 7 — Gestión de reservas | B11: RF-07.6 | C11: Asociar reservas con mesas | D11: EI | E11: Media | F11: =SUMIFS(Parametros!$C$4:$C$12,Parametros!$A$4:$A$12,D11,Parametros!$B$4:$B$12,E11) -> 4 | H11: 8 | I11: Desarrollo: codificación FrontEnd de los módulos | J11: 1 | K11: 1.5 | L11: 2 | M11: =(J11+4*K11+L11)/6 -> 1.5 | N11: =M11*Parametros!$F$20 -> 12 | O11: 7 | P11: Flujo de la iteración
A12: Módulo 7 — Gestión de reservas | B12: RF-07.7 | C12: Verificar disponibilidad de mesas | D12: EQ | E12: Media | F12: =SUMIFS(Parametros!$C$4:$C$12,Parametros!$A$4:$A$12,D12,Parametros!$B$4:$B$12,E12) -> 4 | H12: 9 | I12: Desarrollo: codificación BackEnd de los módulos | J12: 1 | K12: 1.5 | L12: 2 | M12: =(J12+4*K12+L12)/6 -> 1.5 | N12: =M12*Parametros!$F$20 -> 12 | O12: 8 | P12: Flujo de la iteración
A13: Módulo 7 — Gestión de reservas | B13: RF-07.8 | C13: Actualizar estado de reservas | D13: EI | E13: Media | F13: =SUMIFS(Parametros!$C$4:$C$12,Parametros!$A$4:$A$12,D13,Parametros!$B$4:$B$12,E13) -> 4 | H13: 10 | I13: Desarrollo: integración de módulos | J13: 0.5 | K13: 1 | L13: 1.5 | M13: =(J13+4*K13+L13)/6 -> 1 | N13: =M13*Parametros!$F$20 -> 8 | O13: 9 | P13: Flujo de la iteración
C14: Total módulo 7 | F14: =SUM(F6:F13) -> 29 | H14: 11 | I14: Pruebas: elaborar y ejecutar casos de prueba | J14: 0.5 | K14: 0.5 | L14: 0.5 | M14: =(J14+4*K14+L14)/6 -> 0.5 | N14: =M14*Parametros!$F$20 -> 4 | O14: 10 | P14: Flujo de la iteración
A15: Módulo 8 — Gestión de domicilios | B15: RF-08.1 | C15: Registrar pedidos a domicilio | D15: EI | E15: Alta | F15: =SUMIFS(Parametros!$C$4:$C$12,Parametros!$A$4:$A$12,D15,Parametros!$B$4:$B$12,E15) -> 6 | H15: 12 | I15: Pruebas: aceptación y correcciones | J15: 0.5 | K15: 0.5 | L15: 0.5 | M15: =(J15+4*K15+L15)/6 -> 0.5 | N15: =M15*Parametros!$F$20 -> 4 | O15: 11 | P15: Flujo de la iteración
A16: Módulo 8 — Gestión de domicilios | B16: RF-08.2 | C16: Registrar información del cliente | D16: EI | E16: Media | F16: =SUMIFS(Parametros!$C$4:$C$12,Parametros!$A$4:$A$12,D16,Parametros!$B$4:$B$12,E16) -> 4 | H16: 13 | I16: Reunión de cierre y revisión de la iteración | J16: 0.5 | K16: 0.5 | L16: 0.5 | M16: =(J16+4*K16+L16)/6 -> 0.5 | N16: =M16*Parametros!$F$20 -> 4 | O16: 12 | P16: Reunión / seguimiento
A17: Módulo 8 — Gestión de domicilios | B17: RF-08.3 | C17: Registrar dirección de entrega | D17: EI | E17: Media | F17: =SUMIFS(Parametros!$C$4:$C$12,Parametros!$A$4:$A$12,D17,Parametros!$B$4:$B$12,E17) -> 4
A18: Módulo 8 — Gestión de domicilios | B18: RF-08.4 | C18: Consultar pedidos a domicilio | D18: EQ | E18: Media | F18: =SUMIFS(Parametros!$C$4:$C$12,Parametros!$A$4:$A$12,D18,Parametros!$B$4:$B$12,E18) -> 4
A19: Módulo 8 — Gestión de domicilios | B19: RF-08.5 | C19: Asignar pedidos para entrega | D19: EI | E19: Media | F19: =SUMIFS(Parametros!$C$4:$C$12,Parametros!$A$4:$A$12,D19,Parametros!$B$4:$B$12,E19) -> 4
A20: Módulo 8 — Gestión de domicilios | B20: RF-08.6 | C20: Actualizar estado del domicilio | D20: EI | E20: Media | F20: =SUMIFS(Parametros!$C$4:$C$12,Parametros!$A$4:$A$12,D20,Parametros!$B$4:$B$12,E20) -> 4
A21: Módulo 8 — Gestión de domicilios | B21: RF-08.7 | C21: Registrar entrega del pedido | D21: EI | E21: Baja | F21: =SUMIFS(Parametros!$C$4:$C$12,Parametros!$A$4:$A$12,D21,Parametros!$B$4:$B$12,E21) -> 3
A22: Módulo 8 — Gestión de domicilios | B22: RF-08.8 | C22: Consultar historial de domicilios | D22: EQ | E22: Media | F22: =SUMIFS(Parametros!$C$4:$C$12,Parametros!$A$4:$A$12,D22,Parametros!$B$4:$B$12,E22) -> 4
C23: Total módulo 8 | F23: =SUM(F15:F22) -> 33
A26: RESUMEN DE PUNTOS DE FUNCIÓN | H26: ARCHIVOS LÓGICOS INTERNOS (ILF)
A27: Componente | B27: Baja | C27: Media | D27: Alta | E27: PF | H27: ID | I27: Archivo lógico interno | J27: Complejidad | K27: PF
A28: Entrada Externa (EI) | B28: =COUNTIFS($D$6:$D$23,"EI",$E$6:$E$23,"Baja") -> 3 | C28: =COUNTIFS($D$6:$D$23,"EI",$E$6:$E$23,"Media") -> 8 | D28: =COUNTIFS($D$6:$D$23,"EI",$E$6:$E$23,"Alta") -> 1 | E28: =SUMIFS($F$6:$F$23,$D$6:$D$23,"EI") -> 47 | H28: ILF11 | I28: Reservas | J28: Media | K28: =IF(J28="Baja",7,IF(J28="Media",10,15)) -> 10
A29: Salida Externa (EO) | B29: =COUNTIFS($D$6:$D$23,"EO",$E$6:$E$23,"Baja") -> 0 | C29: =COUNTIFS($D$6:$D$23,"EO",$E$6:$E$23,"Media") -> 0 | D29: =COUNTIFS($D$6:$D$23,"EO",$E$6:$E$23,"Alta") -> 0 | E29: =SUMIFS($F$6:$F$23,$D$6:$D$23,"EO") -> 0 | H29: ILF12 | I29: Clientes | J29: Baja | K29: =IF(J29="Baja",7,IF(J29="Media",10,15)) -> 7
A30: Consulta Externa (EQ) | B30: =COUNTIFS($D$6:$D$23,"EQ",$E$6:$E$23,"Baja") -> 1 | C30: =COUNTIFS($D$6:$D$23,"EQ",$E$6:$E$23,"Media") -> 3 | D30: =COUNTIFS($D$6:$D$23,"EQ",$E$6:$E$23,"Alta") -> 0 | E30: =SUMIFS($F$6:$F$23,$D$6:$D$23,"EQ") -> 15 | H30: ILF13 | I30: Domicilios | J30: Alta | K30: =IF(J30="Baja",7,IF(J30="Media",10,15)) -> 15
A31: PF transaccionales | E31: =SUM(E28:E30) -> 62 | J31: Total ILF | K31: =SUM(K28:K30) -> 32
A34: ESTIMACIÓN DE LA ITERACIÓN
A35: PF transaccionales | B35: =E31 -> 62
A36: ILF | B36: =K31 -> 32
A37: PFSA | B37: =B35+B36 -> 94
A38: VAF | B38: =Parametros!$F$4 -> 1.08
A39: PFA | B39: =B37*B38 -> 101.52
A40: LOC/PF Python | B40: =Parametros!$F$6 -> 20
A41: LOC | B41: =B39*B40 -> 2030.4
A42: KLOC | B42: =B41/1000 -> 2.0304
A44: ESFUERZO POR PUNTOS DE FUNCIÓN
A45: PFA de la iteración | B45: =B39 -> 101.52
...

Sheet Iteracion 5
A1: ITERACIÓN 5 — Gestión de pagos + Ventas/consumo + Reportes
H2: PLAN DE ACTIVIDADES Y PERT
A3: Período | B3: 31/10/2026 al 13/11/2026 | C3: Días laborables | D3: 11 | E3: 5 y 6 — Evaluar información de ventas/consumo y diseñar e integrar StockPot. | H3: ID | I3: NOMBRE DE TAREA | J3: TO | K3: TN | L3: TP | M3: TE DÍAS | N3: TE HORAS | O3: DEPENDENCIA | P3: SUPUESTOS
H4: 1 | I4: Reunión de inicio de la iteración | J4: 0.5 | K4: 0.5 | L4: 0.5 | M4: =(J4+4*K4+L4)/6 -> 0.5 | N4: =M4*Parametros!$F$20 -> 4 | P4: Reunión / seguimiento
A5: Módulo | B5: ID | C5: Requerimiento | D5: Tipo | E5: Complejidad | F5: PF | H5: 2 | I5: Planificación y análisis: revisar requerimientos y alcance | J5: 0.5 | K5: 1 | L5: 1.5 | M5: =(J5+4*K5+L5)/6 -> 1 | N5: =M5*Parametros!$F$20 -> 8 | O5: 1 | P5: Flujo de la iteración
A6: Módulo 9 — Gestión de pagos | B6: RF-09.1 | C6: Registrar pagos | D6: EI | E6: Media | F6: =SUMIFS(Parametros!$C$4:$C$12,Parametros!$A$4:$A$12,D6,Parametros!$B$4:$B$12,E6) -> 4 | H6: 3 | I6: Planificación y análisis: validar RF y RNF | J6: 0.5 | K6: 1 | L6: 1.5 | M6: =(J6+4*K6+L6)/6 -> 1 | N6: =M6*Parametros!$F$20 -> 8 | O6: 2 | P6: Flujo de la iteración
A7: Módulo 9 — Gestión de pagos | B7: RF-09.2 | C7: Seleccionar método de pago | D7: EI | E7: Baja | F7: =SUMIFS(Parametros!$C$4:$C$12,Parametros!$A$4:$A$12,D7,Parametros!$B$4:$B$12,E7) -> 3 | H7: 4 | I7: Diseño: definir arquitectura y componentes | J7: 0.5 | K7: 0.5 | L7: 0.5 | M7: =(J7+4*K7+L7)/6 -> 0.5 | N7: =M7*Parametros!$F$20 -> 4 | O7: 3 | P7: Flujo de la iteración
A8: Módulo 9 — Gestión de pagos | B8: RF-09.3 | C8: Calcular valor total del pedido | D8: EO | E8: Media | F8: =SUMIFS(Parametros!$C$4:$C$12,Parametros!$A$4:$A$12,D8,Parametros!$B$4:$B$12,E8) -> 5 | H8: 5 | I8: Diseño: diseñar interfaz de la iteración | J8: 0.5 | K8: 0.5 | L8: 0.5 | M8: =(J8+4*K8+L8)/6 -> 0.5 | N8: =M8*Parametros!$F$20 -> 4 | O8: 4 | P8: Flujo de la iteración
A9: Módulo 9 — Gestión de pagos | B9: RF-09.4 | C9: Consultar estado del pago | D9: EQ | E9: Baja | F9: =SUMIFS(Parametros!$C$4:$C$12,Parametros!$A$4:$A$12,D9,Parametros!$B$4:$B$12,E9) -> 3 | H9: 6 | I9: Diseño: diseñar base de datos de la iteración | J9: 0.5 | K9: 0.5 | L9: 0.5 | M9: =(J9+4*K9+L9)/6 -> 0.5 | N9: =M9*Parametros!$F$20 -> 4 | O9: 5 | P9: Flujo de la iteración
A10: Módulo 9 — Gestión de pagos | B10: RF-09.5 | C10: Asociar pagos con pedidos | D10: EI | E10: Media | F10: =SUMIFS(Parametros!$C$4:$C$12,Parametros!$A$4:$A$12,D10,Parametros!$B$4:$B$12,E10) -> 4 | H10: 7 | I10: Diseño: revisar y aprobar diseño | J10: 0.5 | K10: 0.5 | L10: 0.5 | M10: =(J10+4*K10+L10)/6 -> 0.5 | N10: =M10*Parametros!$F$20 -> 4 | O10: 6 | P10: Flujo de la iteración
A11: Módulo 9 — Gestión de pagos | B11: RF-09.6 | C11: Generar comprobante de pago | D11: EO | E11: Media | F11: =SUMIFS(Parametros!$C$4:$C$12,Parametros!$A$4:$A$12,D11,Parametros!$B$4:$B$12,E11) -> 5 | H11: 8 | I11: Desarrollo: codificación FrontEnd de los módulos | J11: 1 | K11: 1.5 | L11: 2 | M11: =(J11+4*K11+L11)/6 -> 1.5 | N11: =M11*Parametros!$F$20 -> 12 | O11: 7 | P11: Flujo de la iteración
A12: Módulo 9 — Gestión de pagos | B12: RF-09.7 | C12: Consultar historial de pagos | D12: EO | E12: Media | F12: =SUMIFS(Parametros!$C$4:$C$12,Parametros!$A$4:$A$12,D12,Parametros!$B$4:$B$12,E12) -> 5 | H12: 9 | I12: Desarrollo: codificación BackEnd de los módulos | J12: 1 | K12: 1.5 | L12: 2 | M12: =(J12+4*K12+L12)/6 -> 1.5 | N12: =M12*Parametros!$F$20 -> 12 | O12: 8 | P12: Flujo de la iteración
C13: Total módulo 9 | F13: =SUM(F6:F12) -> 29 | H13: 10 | I13: Desarrollo: integración de módulos | J13: 0.5 | K13: 1 | L13: 1.5 | M13: =(J13+4*K13+L13)/6 -> 1 | N13: =M13*Parametros!$F$20 -> 8 | O13: 9 | P13: Flujo de la iteración
A14: Módulo 10 — Ventas y consumo | B14: RF-10.1 | C14: Registrar ventas | D14: EI | E14: Media | F14: =SUMIFS(Parametros!$C$4:$C$12,Parametros!$A$4:$A$12,D14,Parametros!$B$4:$B$12,E14) -> 4 | H14: 11 | I14: Pruebas: elaborar y ejecutar casos de prueba | J14: 0.5 | K14: 0.5 | L14: 0.5 | M14: =(J14+4*K14+L14)/6 -> 0.5 | N14: =M14*Parametros!$F$20 -> 4 | O14: 10 | P14: Flujo de la iteración
A15: Módulo 10 — Ventas y consumo | B15: RF-10.2 | C15: Consultar ventas | D15: EQ | E15: Media | F15: =SUMIFS(Parametros!$C$4:$C$12,Parametros!$A$4:$A$12,D15,Parametros!$B$4:$B$12,E15) -> 4 | H15: 12 | I15: Pruebas: aceptación y correcciones | J15: 0.5 | K15: 0.5 | L15: 0.5 | M15: =(J15+4*K15+L15)/6 -> 0.5 | N15: =M15*Parametros!$F$20 -> 4 | O15: 11 | P15: Flujo de la iteración
H16: 13 | I16: Pruebas: integración final y consolidación de reportes | J16: 0.5 | K16: 1 | L16: 1.5 | M16: =(J16+4*K16+L16)/6 -> 1 | N16: =M16*Parametros!$F$20 -> 8 | O16: 12 | P16: Pruebas de aceptación y correcciones
A17: Módulo 10 — Ventas y consumo | B17: RF-10.3 | C17: Registrar consumo de insumos | D17: EI | E17: Media | F17: =SUMIFS(Parametros!$C$4:$C$12,Parametros!$A$4:$A$12,D17,Parametros!$B$4:$B$12,E17) -> 4 | H17: 14 | I17: Reunión de cierre y revisión de la iteración | J17: 0.5 | K17: 0.5 | L17: 0.5 | M17: =(J17+4*K17+L17)/6 -> 0.5 | N17: =M17*Parametros!$F$20 -> 4 | O17: 13 | P17: Pruebas finalizadas
A18: Módulo 10 — Ventas y consumo | B18: RF-10.4 | C18: Relacionar ventas con productos | D18: EI | E18: Media | F18: =SUMIFS(Parametros!$C$4:$C$12,Parametros!$A$4:$A$12,D18,Parametros!$B$4:$B$12,E18) -> 4
A19: Módulo 10 — Ventas y consumo | B19: RF-10.5 | C19: Consultar productos más vendidos | D19: EO | E19: Media | F19: =SUMIFS(Parametros!$C$4:$C$12,Parametros!$A$4:$A$12,D19,Parametros!$B$4:$B$12,E19) -> 5
A20: Módulo 10 — Ventas y consumo | B20: RF-10.6 | C20: Consultar historial de ventas y consumo | D20: EO | E20: Media | F20: =SUMIFS(Parametros!$C$4:$C$12,Parametros!$A$4:$A$12,D20,Parametros!$B$4:$B$12,E20) -> 5
C21: Total módulo 10 | F21: =SUM(F14:F20) -> 26
A22: Módulo 11 — Reportes y estadísticas | B22: RF-11.1 | C22: Generar reportes de inventario | D22: EO | E22: Media | F22: =SUMIFS(Parametros!$C$4:$C$12,Parametros!$A$4:$A$12,D22,Parametros!$B$4:$B$12,E22) -> 5
A23: Módulo 11 — Reportes y estadísticas | B23: RF-11.2 | C23: Generar reportes de ventas | D23: EO | E23: Media | F23: =SUMIFS(Parametros!$C$4:$C$12,Parametros!$A$4:$A$12,D23,Parametros!$B$4:$B$12,E23) -> 5
A24: Módulo 11 — Reportes y estadísticas | B24: RF-11.3 | C24: Generar reportes de consumo | D24: EO | E24: Media | F24: =SUMIFS(Parametros!$C$4:$C$12,Parametros!$A$4:$A$12,D24,Parametros!$B$4:$B$12,E24) -> 5
A25: Módulo 11 — Reportes y estadísticas | B25: RF-11.4 | C25: Consultar productos más vendidos | D25: EO | E25: Media | F25: =SUMIFS(Parametros!$C$4:$C$12,Parametros!$A$4:$A$12,D25,Parametros!$B$4:$B$12,E25) -> 5
A26: Módulo 11 — Reportes y estadísticas | B26: RF-11.5 | C26: Consultar información histórica | D26: EQ | E26: Media | F26: =SUMIFS(Parametros!$C$4:$C$12,Parametros!$A$4:$A$12,D26,Parametros!$B$4:$B$12,E26) -> 4
A27: Módulo 11 — Reportes y estadísticas | B27: RF-11.6 | C27: Generar estadísticas para apoyar toma de decisiones | D27: EO | E27: Alta | F27: =SUMIFS(Parametros!$C$4:$C$12,Parametros!$A$4:$A$12,D27,Parametros!$B$4:$B$12,E27) -> 7
C28: Total módulo 11 | F28: =SUM(F22:F27) -> 31
A31: RESUMEN DE PUNTOS DE FUNCIÓN | H31: ARCHIVOS LÓGICOS INTERNOS (ILF)
A32: Componente | B32: Baja | C32: Media | D32: Alta | E32: PF | H32: ID | I32: Archivo lógico interno | J32: Complejidad | K32: PF
A33: Entrada Externa (EI) | B33: =COUNTIFS($D$6:$D$27,"EI",$E$6:$E$27,"Baja") -> 1 | C33: =COUNTIFS($D$6:$D$27,"EI",$E$6:$E$27,"Media") -> 5 | D33: =COUNTIFS($D$6:$D$27,"EI",$E$6:$E$27,"Alta") -> 0 | E33: =SUMIFS($F$6:$F$27,$D$6:$D$27,"EI") -> 23 | H33: ILF14 | I33: Pagos | J33: Media | K33: =10 -> 10
A34: Salida Externa (EO) | B34: =COUNTIFS($D$6:$D$27,"EO",$E$6:$E$27,"Baja") -> 0 | C34: =COUNTIFS($D$6:$D$27,"EO",$E$6:$E$27,"Media") -> 9 | D34: =COUNTIFS($D$6:$D$27,"EO",$E$6:$E$27,"Alta") -> 1 | E34: =SUMIFS($F$6:$F$27,$D$6:$D$27,"EO") -> 52 | H34: ILF15 | I34: Ventas | J34: Alta | K34: =15 -> 15
A35: Consulta Externa (EQ) | B35: =COUNTIFS($D$6:$D$27,"EQ",$E$6:$E$27,"Baja") -> 1 | C35: =COUNTIFS($D$6:$D$27,"EQ",$E$6:$E$27,"Media") -> 2 | D35: =COUNTIFS($D$6:$D$27,"EQ",$E$6:$E$27,"Alta") -> 0 | E35: =SUMIFS($F$6:$F$27,$D$6:$D$27,"EQ") -> 11 | H35: ILF16 | I35: Consumo | J35: Media | K35: =10 -> 10
A36: PF transaccionales | E36: =SUM(E33:E35) -> 86 | J36: Total ILF | K36: =SUM(K33:K35) -> 35
A39: ESTIMACIÓN DE LA ITERACIÓN
A40: PF transaccionales | B40: =E36 -> 86
A41: ILF | B41: =K36 -> 35
A42: PFSA | B42: =B40+B41 -> 121
A43: VAF | B43: =Parametros!$F$4 -> 1.08
A44: PFA | B44: =B42*B43 -> 130.68
...

Sheet Consolidado
A1: CONSOLIDADO — PF + ESFUERZO + COCOMO II GLOBAL
A3: Iteración | B3: Módulos | C3: PF transaccionales | D3: ILF | E3: PFSA | F3: VAF | G3: PFA | H3: KLOC | I3: Horas/PF | J3: Horas estimadas | K3: Desarrollo 40% (h)
A4: Iteración 1 | B4: Gestión de usuarios y roles + Gestión de proveedores | C4: ='Iteracion 1'!B34 -> 55 | D4: ='Iteracion 1'!B35 -> 36 | E4: ='Iteracion 1'!B36 -> 91 | F4: ='Iteracion 1'!B37 -> 1.08 | G4: ='Iteracion 1'!B38 -> 98.28 | H4: ='Iteracion 1'!B41 -> 1.9656 | I4: =Parametros!$F$19 -> 6 | J4: =G4*I4 -> 589.68 | K4: =J4*Parametros!$F$26 -> 235.872
A5: Iteración 2 | B5: Gestión de inventario + Productos y menú | C5: ='Iteracion 2'!B35 -> 59 | D5: ='Iteracion 2'!B36 -> 50 | E5: ='Iteracion 2'!B37 -> 109 | F5: ='Iteracion 2'!B38 -> 1.08 | G5: ='Iteracion 2'!B39 -> 117.72 | H5: ='Iteracion 2'!B42 -> 2.3544 | I5: =Parametros!$F$19 -> 6 | J5: =G5*I5 -> 706.32 | K5: =J5*Parametros!$F$26 -> 282.528
A6: Iteración 3 | B6: Gestión de pedidos + Gestión de cocina | C6: ='Iteracion 3'!B35 -> 68 | D6: ='Iteracion 3'!B36 -> 32 | E6: ='Iteracion 3'!B37 -> 100 | F6: ='Iteracion 3'!B38 -> 1.08 | G6: ='Iteracion 3'!B39 -> 108 | H6: ='Iteracion 3'!B42 -> 2.16 | I6: =Parametros!$F$19 -> 6 | J6: =G6*I6 -> 648 | K6: =J6*Parametros!$F$26 -> 259.2
A7: Iteración 4 | B7: Gestión de reservas + Gestión de domicilios | C7: ='Iteracion 4'!B35 -> 62 | D7: ='Iteracion 4'!B36 -> 32 | E7: ='Iteracion 4'!B37 -> 94 | F7: ='Iteracion 4'!B38 -> 1.08 | G7: ='Iteracion 4'!B39 -> 101.52 | H7: ='Iteracion 4'!B42 -> 2.0304 | I7: =Parametros!$F$19 -> 6 | J7: =G7*I7 -> 609.12 | K7: =J7*Parametros!$F$26 -> 243.648
A8: Iteración 5 | B8: Gestión de pagos + Ventas/consumo + Reportes | C8: ='Iteracion 5'!B40 -> 86 | D8: ='Iteracion 5'!B41 -> 35 | E8: ='Iteracion 5'!B42 -> 121 | F8: ='Iteracion 5'!B43 -> 1.08 | G8: ='Iteracion 5'!B44 -> 130.68 | H8: ='Iteracion 5'!B47 -> 2.6136 | I8: =Parametros!$F$19 -> 6 | J8: =G8*I8 -> 784.08 | K8: =J8*Parametros!$F$26 -> 313.632
A9: TOTAL | C9: =SUM(C4:C8) -> 330 | D9: =SUM(D4:D8) -> 185 | E9: =SUM(E4:E8) -> 515 | F9: =Parametros!$F$4 -> 1.08 | G9: =SUM(G4:G8) -> 556.2 | H9: =SUM(H4:H8) -> 11.124 | I9: =Parametros!$F$19 -> 6 | J9: =SUM(J4:J8) -> 3337.2 | K9: =SUM(K4:K8) -> 1334.88
A12: COCOMO II — APLICACIÓN ÚNICA AL PROYECTO COMPLETO
A13: KLOC global | C13: =H9 -> 11.124
A14: Modelo | C14: Orgánico
A15: a | C15: =Parametros!$F$7 -> 2.4
A16: b | C16: =Parametros!$F$8 -> 1.05
A17: c | C17: =Parametros!$F$9 -> 2.5
A18: d | C18: =Parametros!$F$10 -> 0.38
A19: Esfuerzo global (PM) | C19: =C15*C13^C16 -> 30.115167
A20: TDEV global (meses) | C20: =C17*C19^C18 -> 9.1175554
A21: Desarrolladores según COCOMO | C21: =ROUNDUP(C19/C20,0) -> 4
A22: Duración calendario proyecto (meses) | C22: =Parametros!$F$14 -> 3.2
A23: Inicio desarrollo | C23: =Parametros!$F$24 -> 46279
A24: Nota | C24: COCOMO II se aplica una sola vez al proyecto completo. Las iteraciones se estiman con PF y el 40% de desarrollo se controla como esfuerzo.
A25: Nota metodológica
A26: COCOMO II se aplica una sola vez al proyecto completo. Las iteraciones se estiman con Puntos de Función y se consolidan antes de calcular COCOMO. El TDEV de 9,30 meses es el resultado teórico del modelo; el cronograma académico es fijo de 10 semanas.
A27: DISTRIBUCIÓN DE ESFUERZO POR FASE (GUÍA DEL EJEMPLO)
A28: Fase | B28: % | C28: Horas | D28: Días-persona a 8 h
A29: Planificación y análisis | B29: 0.25 | C29: =J9*B29 -> 834.3 | D29: =C29/Parametros!$F$20 -> 104.2875
A30: Diseño | B30: 0.25 | C30: =J9*B30 -> 834.3 | D30: =C30/Parametros!$F$20 -> 104.2875
A31: Desarrollo | B31: 0.4 | C31: =J9*B31 -> 1334.88 | D31: =C31/Parametros!$F$20 -> 166.86
A32: Pruebas | B32: 0.1 | C32: =J9*B32 -> 333.72 | D32: =C32/Parametros!$F$20 -> 41.715
A33: TOTAL | B33: =SUM(B29:B32) -> 1 | C33: =SUM(C29:C32) -> 3337.2 | D33: =SUM(D29:D32) -> 417.15

Sheet wbs-EDT
A1: WBS/EDT + PERT — StockPot — 10/08/2026 a 13/11/2026
A2: Proyecto | B2: StockPot
A3: Jornada | B3: Lunes a sábado, 8 horas/día; domingos y festivos no laborables
A4: Inicio del desarrollo | B4: 14/09/2026
A5: Fin del desarrollo | B5: 13/11/2026
A6: Iteraciones | B6: 5 iteraciones: 10/10/10/10/11 días laborables
A8: Código | B8: Fase | C8: Inicio | D8: Fin | E8: Dependencia | F8: Resultado / entregable
A9: 1 | B9: Inicio del proyecto | C9: 46244 | D9: 46244 | E9: — | F9: Acta, alcance e interesados
A10: 2 | B10: Planificación y análisis del sistema | C10: 46245 | D10: 46269 | E10: 1 | F10: Requerimientos, RF/RNF y planificación
A11: 3 | B11: Diseño del sistema | C11: 46272 | D11: 46276 | E11: 2 | F11: Arquitectura, interfaz y BD
A12: 4 | B12: Desarrollo del sistema | C12: 46279 | D12: 46339 | E12: 3 | F12: Incrementos de StockPot
A13: 5 | B13: Pruebas | C13: 46279 | D13: 46339 | E13: 4 | F13: Pruebas dentro de cada iteración y cierre final
A14: 6 | B14: Implementación | C14: 46339 | D14: 46339 | E14: 5 | F14: Versión preparada para implementación
A15: 7 | B15: Cierre del proyecto | C15: 46339 | D15: 46339 | E15: 6 | F15: Documentación y cierre
A17: Iteración | B17: Período | C17: Módulos | D17: PF transaccionales | E17: Reunión inicio | F17: Reunión cierre | G17: Dependencia
A18: Iteración 1 | B18: 14/09/2026 - 24/09/2026 | C18: Gestión de usuarios y roles + Gestión de proveedores | D18: 55 | E18: 46279 | F18: 46289 | G18: Fase 3
A19: Iteración 2 | B19: 25/09/2026 - 06/10/2026 | C19: Gestión de inventario + Productos y menú | D19: 59 | E19: 46290 | F19: 46301 | G19: Iteración 1
A20: Iteración 3 | B20: 07/10/2026 - 19/10/2026 | C20: Gestión de pedidos + Gestión de cocina | D20: 68 | E20: 46302 | F20: 46314 | G20: Iteración 2
A21: Iteración 4 | B21: 20/10/2026 - 30/10/2026 | C21: Gestión de reservas + Gestión de domicilios | D21: 62 | E21: 46315 | F21: 46325 | G21: Iteración 3
A22: Iteración 5 | B22: 31/10/2026 - 13/11/2026 | C22: Gestión de pagos + Ventas/consumo + Reportes | D22: 86 | E22: 46326 | F22: 46339 | G22: Iteración 4

Sheet costos y roles
A1: COSTOS Y ROLES — CRONOGRAMA ACADÉMICO DE 10 SEMANAS
A3: Rol | B3: Cantidad | C3: Tiempo (meses) | D3: Salario mensual | E3: Costo total
A4: Desarrolladores | B4: =Consolidado!C21 -> 4 | C4: =Parametros!$F$14 -> 3.2 | D4: =Parametros!$F$15 -> 1732412 | E4: =B4*C4*D4*1 -> 22174874
A5: Administrador/Gestor del proyecto | B5: 1 | C5: =Parametros!$F$14 -> 3.2 | D5: =Parametros!$F$16 -> 2645765 | E5: =B5*C5*D5*1 -> 8466448
A6: Arquitecto de base de datos | B6: 1 | C6: 1 | D6: =Parametros!$F$17 -> 3600000 | E6: =B6*C6*D6*0.5 -> 1800000
A7: QA / Analista de calidad | B7: 1 | C7: 1 | D7: =Parametros!$F$18 -> 2539000 | E7: =B7*C7*D7*1 -> 2539000
A8: Subtotal personal | E8: =SUM(E4:E7) -> 34980322
A10: Nota | B10: El costo usa el calendario académico de 10 semanas. COCOMO II se aplica una sola vez y su TDEV teórico de 9,30 meses se conserva como resultado del modelo.

Sheet presupuesto y BAC
A1: PRESUPUESTO Y BAC — 10 SEMANAS
A3: Recurso | B3: Cantidad | C3: Tiempo (meses) | D3: Salario mensual | E3: Costo total | G3: INDICADOR | H3: VALOR
A4: Desarrolladores | B4: =Consolidado!C21 -> 4 | C4: =Parametros!$F$14 -> 3.2 | D4: =Parametros!$F$15 -> 1732412 | E4: =B4*C4*D4 -> 22174874 | G4: BAC académico 10 semanas | H4: =E8+D20 -> 43980322
A5: Administrador/Gestor del proyecto | B5: 1 | C5: =Parametros!$F$14 -> 3.2 | D5: =Parametros!$F$16 -> 2645765 | E5: =B5*C5*D5 -> 8466448 | G5: Esfuerzo COCOMO global (PM) | H5: =Consolidado!C19 -> 30.115167
A6: Arquitecto de base de datos | B6: 1 | C6: 1 | D6: =Parametros!$F$17 -> 3600000 | E6: =B6*C6*D6*0.5 -> 1800000 | G6: TDEV COCOMO global (meses) | H6: =Consolidado!C20 -> 9.1175554
A7: QA / Analista de calidad | B7: 1 | C7: 1 | D7: =Parametros!$F$18 -> 2539000 | E7: =B7*C7*D7 -> 2539000 | G7: Desarrolladores según COCOMO | H7: =Consolidado!C21 -> 4
A8: Subtotal personal | E8: =SUM(E4:E7) -> 34980322 | G8: Duración académica (meses) | H8: =Parametros!$F$14 -> 3.2
G9: Desarrolladores para comprimir a 10 semanas | H9: =Consolidado!C23 -> 46279
A11: Recursos y materiales | G11: Nota metodológica
A12: Recurso | B12: Cantidad | C12: Costo unitario | D12: Costo total | G12: El BAC usa el cronograma académico de 10 semanas. COCOMO se calcula una sola vez sobre 11,68 KLOC. El modelo arroja 31,70 PM y 9,30 meses teóricos; no se suman esfuerzos de COCOMO por iteración.
A13: Servicio de hosting durante el proyecto | B13: 1 | C13: 1200000 | D13: =B13*C13 -> 1200000
A14: Dominio web | B14: 1 | C14: 100000 | D14: =B14*C14 -> 100000
A15: Servicios de almacenamiento/respaldo | B15: 1 | C15: 500000 | D15: =B15*C15 -> 500000
A16: Equipos y periféricos de apoyo | B16: 4 | C16: 1000000 | D16: =B16*C16 -> 4000000
A17: Material de capacitación/documentación | B17: 1 | C17: 500000 | D17: =B17*C17 -> 500000
